<?xml version="1.0" ?>
<!-- =================================================================================== -->
<!-- |    This document was autogenerated by xacro from robot.xacro                    | -->
<!-- |    EDITING THIS FILE BY HAND IS NOT RECOMMENDED                                 | -->
<!-- =================================================================================== -->
<robot name="prismatic_cartesian_robot">
  <link name="base_link">
    <visual>
      <origin rpy="0 0 0" xyz="15 0 0"/>
      <geometry>
        <box size="30 0.18 0.18"/>
      </geometry>
    </visual>
  </link>
  <joint name="x" type="prismatic">
    <origin rpy="0 0 0" xyz="0.09 4.91 0.18"/>
    <axis xyz="1 0 0"/>
    <limit effort="100" lower="0" upper="30" velocity="1"/>
    <parent link="base_link"/>
    <child link="link1"/>
  </joint>
  <link name="link1">
    <visual>
      <origin rpy="0 0 0" xyz="0 0 0"/>
      <geometry>
        <box size="0.18 10 0.18"/>
      </geometry>
      <material name="Green1">
        <color rgba="0 1 0 1"/>
      </material>
    </visual>
  </link>
  <joint name="y" type="prismatic">
    <origin rpy="0 0 0" xyz="0 -4.73 0.18"/>
    <axis xyz="0 1 0"/>
    <limit effort="100" lower="0" upper="9.46" velocity="1"/>
    <parent link="link1"/>
    <child link="link2"/>
  </joint>
  <link name="link2">
    <visual>
      <origin rpy="0 0 0" xyz="0 0 0"/>
      <geometry>
        <box size="0.18 0.18 0.18"/>
      </geometry>
      <material name="Cyan1">
        <color rgba="0 0.9 0.9 1.0"/>
      </material>
    </visual>
  </link>
  <joint name="z" type="prismatic">
    <origin rpy="0 0 0" xyz="0.18 0 0"/>
    <axis xyz="0 0 1"/>
    <limit effort="100" lower="-9.64" upper="0" velocity="1"/>
    <parent link="link2"/>
    <child link="link3"/>
  </joint>
  <link name="link3">
    <visual>
      <origin rpy="0 0 0" xyz="0 0 0"/>
      <geometry>
        <box size="0.18 0.18 0.18"/>
      </geometry>
      <material name="Yellow2">
        <color rgba="0.8 0.8 0 1.0"/>
      </material>
    </visual>
  </link>
</robot>
